<?xml version="1.0" ?>
<robot name="arm5dof">
<link name="world"/>
<link name="base_link">
  <inertial>
    <origin rpy="0 0 0" xyz="7e-06 0.03889 0.07653"/>
    <mass value="5.271966"/>
    <inertia ixx="0.032682" ixy="-5e-06" ixz="1e-06" iyy="0.021924" iyz="0.001866" izz="0.030508"/>
  </inertial>
  <visual>
    <origin rpy="0 0 0" xyz="0 0 0"/>
    <geometry>
      <mesh filename="package://futaba_robot/src/bin_stl/base_link_m-binary.stl"/>
    </geometry>
    <material name="silver">
      <color rgba="1 0 0 1"/>
    </material>
  </visual>
  <collision>
    <origin rpy="0 0 0" xyz="0 0 0"/>
    <geometry>
      <mesh filename="package://futaba_robot/src/bin_stl/base_link_m-binary.stl"/>
    </geometry>
  </collision>
</link>
<link name="link3s__1">
  <inertial>
    <origin rpy="0 0 0" xyz="-0.042829000000000006 2.3e-05 0.06906599999999996"/>
    <mass value="1.684049"/>
    <inertia ixx="0.007772" ixy="-0.0" ixz="1.3e-05" iyy="0.008317" iyz="5e-05" izz="0.002924"/>
  </inertial>
  <visual>
    <origin rpy="0 0 0" xyz="-0.0425 -0.0 -0.55"/>
    <geometry>
      <mesh filename="package://futaba_robot/src/bin_stl/link3s__1_m-binary.stl"/>
    </geometry>
    <material name="silver">
      <color rgba="1 0 0 1"/>
    </material>
  </visual>
  <collision>
    <origin rpy="0 0 0" xyz="-0.0425 -0.0 -0.55"/>
    <geometry>
      <mesh filename="package://futaba_robot/src/bin_stl/link3s__1_m-binary.stl"/>
    </geometry>
  </collision>
</link>
<link name="link4s__1">
  <inertial>
    <origin rpy="0 0 0" xyz="-0.022 0.0 -0.005205999999999933"/>
    <mass value="0.32285"/>
    <inertia ixx="0.000412" ixy="0.0" ixz="-0.0" iyy="0.0003" iyz="0.0" izz="0.000217"/>
  </inertial>
  <visual>
    <origin rpy="0 0 0" xyz="-0.022 0.0 -0.71"/>
    <geometry>
      <mesh filename="package://futaba_robot/src/bin_stl/link4s__1_m-binary.stl"/>
    </geometry>
    <material name="silver">
      <color rgba="1 0 0 1"/>
    </material>
  </visual>
  <collision>
    <origin rpy="0 0 0" xyz="-0.022 0.0 -0.71"/>
    <geometry>
      <mesh filename="package://futaba_robot/src/bin_stl/link4s__1_m-binary.stl"/>
    </geometry>
  </collision>
</link>
<link name="link1s__1">
  <inertial>
    <origin rpy="0 0 0" xyz="1e-06 0.007169 0.08051"/>
    <mass value="2.279281"/>
    <inertia ixx="0.009614" ixy="0.0" ixz="0.0" iyy="0.009161" iyz="0.000188" izz="0.00513"/>
  </inertial>
  <visual>
    <origin rpy="0 0 0" xyz="0.0 0.0 -0.168"/>
    <geometry>
      <mesh filename="package://futaba_robot/src/bin_stl/link1s__1_m-binary.stl"/>
    </geometry>
    <material name="silver">
      <color rgba="1 0 0 1"/>
    </material>
  </visual>
  <collision>
    <origin rpy="0 0 0" xyz="0.0 0.0 -0.168"/>
    <geometry>
      <mesh filename="package://futaba_robot/src/bin_stl/link1s__1_m-binary.stl"/>
    </geometry>
  </collision>
</link>
<link name="link2s__1">
  <inertial>
    <origin rpy="0 0 0" xyz="-0.0455 0.000459 0.115006"/>
    <mass value="3.654454"/>
    <inertia ixx="0.029584" ixy="-0.0" ixz="-0.0" iyy="0.039619" iyz="-7.1e-05" izz="0.015467"/>
  </inertial>
  <visual>
    <origin rpy="0 0 0" xyz="-0.0455 -0.0 -0.3"/>
    <geometry>
      <mesh filename="package://futaba_robot/src/bin_stl/link2s__1_m-binary.stl"/>
    </geometry>
    <material name="silver">
      <color rgba="1 0 0 1"/>
    </material>
  </visual>
  <collision>
    <origin rpy="0 0 0" xyz="-0.0455 -0.0 -0.3"/>
    <geometry>
      <mesh filename="package://futaba_robot/src/bin_stl/link2s__1_m-binary.stl"/>
    </geometry>
  </collision>
</link>
<joint name="fixed" type="fixed">
  <parent link="world"/>
  <child link="base_link"/>
</joint>
<joint name="servo1" type="continuous">
  <origin rpy="0 0 0" xyz="0.0 0.0 0.168"/>
  <parent link="base_link"/>
  <child link="link1s__1"/>
  <axis xyz="0.0 0.0 0.01"/>
</joint>
<transmission name="servo1_tran">
  <type>transmission_interface/SimpleTransmission</type>
  <joint name="servo1">
    <hardwareInterface>PositionJointInterface</hardwareInterface>
  </joint>
  <actuator name="servo1_actr">
    <hardwareInterface>PositionJointInterface</hardwareInterface>
    <mechanicalReduction>1</mechanicalReduction>
  </actuator>
</transmission>
<joint name="servo2" type="continuous">
  <origin rpy="0 0 0" xyz="0.0455 0.0 0.132"/>
  <parent link="link1s__1"/>
  <child link="link2s__1"/>
  <axis xyz="0.01 0.0 0.0"/>
</joint>
<transmission name="servo2_tran">
  <type>transmission_interface/SimpleTransmission</type>
  <joint name="servo2">
    <hardwareInterface>PositionJointInterface</hardwareInterface>
  </joint>
  <actuator name="servo2_actr">
    <hardwareInterface>PositionJointInterface</hardwareInterface>
    <mechanicalReduction>1</mechanicalReduction>
  </actuator>
</transmission>
<joint name="servo3" type="continuous">
  <origin rpy="0 0 0" xyz="-0.003 0.0 0.25"/>
  <parent link="link2s__1"/>
  <child link="link3s__1"/>
  <axis xyz="-0.01 -0.0 -0.0"/>
</joint>
<transmission name="servo3_tran">
  <type>transmission_interface/SimpleTransmission</type>
  <joint name="servo3">
    <hardwareInterface>PositionJointInterface</hardwareInterface>
  </joint>
  <actuator name="servo3_actr">
    <hardwareInterface>PositionJointInterface</hardwareInterface>
    <mechanicalReduction>1</mechanicalReduction>
  </actuator>
</transmission>
<joint name="servo4" type="continuous">
  <origin rpy="0 0 0" xyz="-0.0205 -0.0 0.16"/>
  <parent link="link3s__1"/>
  <child link="link4s__1"/>
  <axis xyz="-0.01 -0.0 0.0"/>
</joint>
<transmission name="servo4_tran">
  <type>transmission_interface/SimpleTransmission</type>
  <joint name="servo4">
    <hardwareInterface>PositionJointInterface</hardwareInterface>
  </joint>
  <actuator name="servo4_actr">
    <hardwareInterface>PositionJointInterface</hardwareInterface>
    <mechanicalReduction>1</mechanicalReduction>
  </actuator>
</transmission>
<gazebo>
  <plugin name="control" filename="libgazebo_ros_control.so"/>
  <plugin name="joint_state_publisher" filename="libgazebo_ros_joint_state_publisher.so">
    <jointName>servo1, servo2, servo3, servo4</jointName>
  </plugin>
</gazebo>
</robot>
